<?xml version="1.0" ?>
<!-- =================================================================================== -->
<!-- |    This document was autogenerated by xacro from ../spot_urdf/urdf/spot.urdf.xacro | -->
<!-- |    EDITING THIS FILE BY HAND IS NOT RECOMMENDED                                 | -->
<!-- =================================================================================== -->
<robot name="spot">
  <gazebo>
    <plugin filename="libxbot2_gz_link_state_sensor.so" name="xbot2_link_state_sensor">
      <links>
        <link name="base_link"/>
      </links>
    </plugin>
    <plugin filename="libxbot2_gz_ft_server.so" name="xbot2_gz_ft_server"/>
    <plugin filename="libxbot2_gz_imu_server.so" name="xbot2_gz_imu_server"/>
    <plugin filename="libxbot2_gz_joint_server.so" name="xbot2_gz_joint_server">
      <pid>
        <gain d="5" name="small_mot" p="700"/>
        <gain d="10" name="med_mot" p="1500"/>
        <gain d="20" name="bigl_mot" p="3000"/>
        <pid name="lf_haa_joint" profile="med_mot"/>
        <pid name="lf_hfe_joint" profile="med_mot"/>
        <pid name="lf_kfe_joint" profile="small_mot"/>
        <pid name="rf_haa_joint" profile="med_mot"/>
        <pid name="rf_hfe_joint" profile="med_mot"/>
        <pid name="rf_kfe_joint" profile="small_mot"/>
        <pid name="lh_haa_joint" profile="med_mot"/>
        <pid name="lh_hfe_joint" profile="med_mot"/>
        <pid name="lh_kfe_joint" profile="small_mot"/>
        <pid name="rh_haa_joint" profile="med_mot"/>
        <pid name="rh_hfe_joint" profile="med_mot"/>
        <pid name="rh_kfe_joint" profile="small_mot"/>
      </pid>
    </plugin>
  </gazebo>
  <!-- Floating-base Joint -->
  <link name="world"/>
  <joint name="floating_base_joint" type="floating">
    <origin rpy="0 0 0" xyz="0 0 0"/>
    <parent link="world"/>
    <child link="base_link"/>
  </joint>
  <link name="base_link">
    <visual>
      <geometry>
        <mesh filename="package://spot_urdf/meshes/body.dae"/>
      </geometry>
    </visual>
    <collision>
      <geometry>
        <mesh filename="package://spot_urdf/meshes/body_collision.stl"/>
      </geometry>
    </collision>
    <inertial>
      <origin rpy="0 0 0" xyz="0.008465 0.004045 -0.000763"/>
      <mass value="11.041"/>
      <inertia ixx="0.050874" ixy="-0.000451628" ixz="0.000487603" iyy="0.64036" iyz="4.8356e-05" izz="0.65655"/>
    </inertial>
  </link>
  <link name="front_rail"/>
  <joint name="front_rail_joint" type="fixed">
    <origin rpy="0 0 0" xyz="0.223 0 0.0805"/>
    <parent link="base_link"/>
    <child link="front_rail"/>
  </joint>
  <link name="rear_rail"/>
  <joint name="rear_rail_joint" type="fixed">
    <origin rpy="0 0 0" xyz="-0.223 0 0.0805"/>
    <parent link="base_link"/>
    <child link="rear_rail"/>
  </joint>
  <link name="lf_hip">
    <visual>
      <geometry>
        <mesh filename="package://spot_urdf/meshes/front_left_hip.dae"/>
      </geometry>
    </visual>
    <collision>
      <geometry>
        <mesh filename="package://spot_urdf/meshes/front_left_hip_collision.stl"/>
      </geometry>
    </collision>
    <inertial>
      <origin rpy="0 0 0" xyz="-0.022191 0.015144 -1.5e-05"/>
      <mass value="1.993"/>
      <inertia ixx="0.002903894" ixy="-7.185e-05" ixz="-1.262e-06" iyy="0.004907517" iyz="-1.75e-06" izz="0.005586944"/>
    </inertial>
  </link>
  <joint name="lf_haa_joint" type="revolute">
    <origin rpy="0 0 0" xyz="0.29785 0.05500 0.00000"/>
    <axis xyz="1 0 0"/>
    <parent link="base_link"/>
    <child link="lf_hip"/>
    <limit effort="1000" lower="-0.78539816339744827899" upper="0.78539816339744827899" velocity="1000.00"/>
  </joint>
  <link name="lf_upperleg">
    <visual>
      <geometry>
        <mesh filename="package://spot_urdf/meshes/front_left_upper_leg.dae"/>
      </geometry>
    </visual>
    <collision>
      <geometry>
        <mesh filename="package://spot_urdf/meshes/front_left_upper_leg_collision.stl"/>
      </geometry>
    </collision>
    <inertial>
      <origin rpy="0 0 0" xyz="-0.005607 -0.003877 -0.048199"/>
      <mass value="0.639"/>
      <inertia ixx="0.005666803" ixy="3.597e-06" ixz="0.000491446" iyy="0.005847229" iyz="1.0086e-05" izz="0.000369811"/>
    </inertial>
  </link>
  <joint name="lf_hfe_joint" type="revolute">
    <origin rpy="0 0 0" xyz="0.0 0.110945 0.0"/>
    <axis xyz="0 1 0"/>
    <parent link="lf_hip"/>
    <child link="lf_upperleg"/>
    <limit effort="1000" lower="-0.89884456477707963539" upper="2.2951079663725435509" velocity="1000.00"/>
  </joint>
  <link name="lf_lowerleg">
    <visual>
      <geometry>
        <mesh filename="package://spot_urdf/meshes/front_left_lower_leg.dae"/>
      </geometry>
    </visual>
    <collision>
      <geometry>
        <mesh filename="package://spot_urdf/meshes/front_left_lower_leg_collision.stl"/>
      </geometry>
    </collision>
    <inertial>
      <origin rpy="0 0 0" xyz="0.002781 6.3e-05 -0.142518"/>
      <mass value="0.207"/>
      <inertia ixx="0.006341369" ixy="-3e-09" ixz="-8.7951e-05" iyy="0.006355157" iyz="-1.336e-06" izz="3.9188e-05"/>
    </inertial>
  </link>
  <joint name="lf_kfe_joint" type="revolute">
    <origin rpy="0 0 0" xyz="0.025 0.000 -0.3205"/>
    <axis xyz="0 1 0"/>
    <parent link="lf_upperleg"/>
    <child link="lf_lowerleg"/>
    <limit effort="1000" lower="-2.7929" upper="-0.254801" velocity="1000.00"/>
  </joint>
  <joint name="lf_foot_joint" type="fixed">
    <origin rpy="0 0 0" xyz="-0.005 0.0 -0.348"/>
    <parent link="lf_lowerleg"/>
    <child link="lf_foot"/>
  </joint>
  <link name="lf_foot">
    <visual>
      <origin rpy="0 0 0" xyz="0 0 0"/>
      <geometry>
        <sphere radius="0.019999999999999997"/>
      </geometry>
      <material name="green">
        <color rgba="0.0 0.8 0.0 1.0"/>
      </material>
    </visual>
    <collision>
      <origin rpy="0 0 0" xyz="0 0 0"/>
      <geometry>
        <sphere radius="0.03"/>
      </geometry>
    </collision>
    <inertial>
      <mass value="0.06"/>
      <inertia ixx="2.16e-05" ixy="0.0" ixz="0.0" iyy="2.16e-05" iyz="0.0" izz="2.16e-05"/>
    </inertial>
  </link>
  <link name="rf_hip">
    <visual>
      <geometry>
        <mesh filename="package://spot_urdf/meshes/front_right_hip.dae"/>
      </geometry>
    </visual>
    <collision>
      <geometry>
        <mesh filename="package://spot_urdf/meshes/front_right_hip_collision.stl"/>
      </geometry>
    </collision>
    <inertial>
      <origin rpy="0 0 0" xyz="-0.022191 -0.015144 -1.5e-05"/>
      <mass value="1.993"/>
      <inertia ixx="0.002903894" ixy="7.185e-05" ixz="-1.262e-06" iyy="0.004907517" iyz="1.75e-06" izz="0.005586944"/>
    </inertial>
  </link>
  <joint name="rf_haa_joint" type="revolute">
    <origin rpy="0 0 0" xyz="0.29785 -0.05500 0.00000"/>
    <axis xyz="1 0 0"/>
    <parent link="base_link"/>
    <child link="rf_hip"/>
    <limit effort="1000" lower="-0.78539816339744827899" upper="0.78539816339744827899" velocity="1000.00"/>
  </joint>
  <link name="rf_upperleg">
    <visual>
      <geometry>
        <mesh filename="package://spot_urdf/meshes/front_right_upper_leg.dae"/>
      </geometry>
    </visual>
    <collision>
      <geometry>
        <mesh filename="package://spot_urdf/meshes/front_right_upper_leg_collision.stl"/>
      </geometry>
    </collision>
    <inertial>
      <origin rpy="0 0 0" xyz="-0.005607 0.003877 -0.048199"/>
      <mass value="0.639"/>
      <inertia ixx="0.005666803" ixy="-3.597e-06" ixz="0.000491446" iyy="0.005847229" iyz="-1.0086e-05" izz="0.000369811"/>
    </inertial>
  </link>
  <joint name="rf_hfe_joint" type="revolute">
    <origin rpy="0 0 0" xyz="0.0 -0.110945 0.0"/>
    <axis xyz="0 1 0"/>
    <parent link="rf_hip"/>
    <child link="rf_upperleg"/>
    <limit effort="1000" lower="-0.89884456477707963539" upper="2.2951079663725435509" velocity="1000.00"/>
  </joint>
  <link name="rf_lowerleg">
    <visual>
      <geometry>
        <mesh filename="package://spot_urdf/meshes/front_right_lower_leg.dae"/>
      </geometry>
    </visual>
    <collision>
      <geometry>
        <mesh filename="package://spot_urdf/meshes/front_right_lower_leg_collision.stl"/>
      </geometry>
    </collision>
    <inertial>
      <origin rpy="0 0 0" xyz="0.002781 -6.3e-05 -0.142518"/>
      <mass value="0.207"/>
      <inertia ixx="0.006341369" ixy="3e-09" ixz="-8.7951e-05" iyy="0.006355157" iyz="1.336e-06" izz="3.9188e-05"/>
    </inertial>
  </link>
  <joint name="rf_kfe_joint" type="revolute">
    <origin rpy="0 0 0" xyz="0.025 0.000 -0.3205"/>
    <axis xyz="0 1 0"/>
    <parent link="rf_upperleg"/>
    <child link="rf_lowerleg"/>
    <limit effort="1000" lower="-2.7929" upper="-0.247563" velocity="1000.00"/>
  </joint>
  <joint name="rf_foot_joint" type="fixed">
    <origin rpy="0 0 0" xyz="-0.005 0.0 -0.348"/>
    <parent link="rf_lowerleg"/>
    <child link="rf_foot"/>
  </joint>
  <link name="rf_foot">
    <visual>
      <origin rpy="0 0 0" xyz="0 0 0"/>
      <geometry>
        <sphere radius="0.019999999999999997"/>
      </geometry>
      <material name="green">
        <color rgba="0.0 0.8 0.0 1.0"/>
      </material>
    </visual>
    <collision>
      <origin rpy="0 0 0" xyz="0 0 0"/>
      <geometry>
        <sphere radius="0.03"/>
      </geometry>
    </collision>
    <inertial>
      <mass value="0.06"/>
      <inertia ixx="2.16e-05" ixy="0.0" ixz="0.0" iyy="2.16e-05" iyz="0.0" izz="2.16e-05"/>
    </inertial>
  </link>
  <link name="lh_hip">
    <visual>
      <geometry>
        <mesh filename="package://spot_urdf/meshes/rear_left_hip.dae"/>
      </geometry>
    </visual>
    <collision>
      <geometry>
        <mesh filename="package://spot_urdf/meshes/rear_left_hip_collision.stl"/>
      </geometry>
    </collision>
    <inertial>
      <origin rpy="0 0 0" xyz="0.022191 0.015144 -1.5e-05"/>
      <mass value="1.993"/>
      <inertia ixx="0.002903894" ixy="7.185e-05" ixz="1.262e-06" iyy="0.004907517" iyz="-1.75e-06" izz="0.005586944"/>
    </inertial>
  </link>
  <joint name="lh_haa_joint" type="revolute">
    <origin rpy="0 0 0" xyz="-0.29785 0.05500 0.00000"/>
    <axis xyz="1 0 0"/>
    <parent link="base_link"/>
    <child link="lh_hip"/>
    <limit effort="1000" lower="-0.78539816339744827899" upper="0.78539816339744827899" velocity="1000.00"/>
  </joint>
  <link name="lh_upperleg">
    <visual>
      <geometry>
        <mesh filename="package://spot_urdf/meshes/rear_left_upper_leg.dae"/>
      </geometry>
    </visual>
    <collision>
      <geometry>
        <mesh filename="package://spot_urdf/meshes/rear_left_upper_leg_collision.stl"/>
      </geometry>
    </collision>
    <inertial>
      <origin rpy="0 0 0" xyz="-0.005607 -0.003877 -0.048199"/>
      <mass value="0.639"/>
      <inertia ixx="0.005666803" ixy="3.597e-06" ixz="0.000491446" iyy="0.005847229" iyz="1.0086e-05" izz="0.000369811"/>
    </inertial>
  </link>
  <joint name="lh_hfe_joint" type="revolute">
    <origin rpy="0 0 0" xyz="0.0 0.110945 0.0"/>
    <axis xyz="0 1 0"/>
    <parent link="lh_hip"/>
    <child link="lh_upperleg"/>
    <limit effort="1000" lower="-0.89884456477707963539" upper="2.2951079663725435509" velocity="1000.00"/>
  </joint>
  <link name="lh_lowerleg">
    <visual>
      <geometry>
        <mesh filename="package://spot_urdf/meshes/rear_left_lower_leg.dae"/>
      </geometry>
    </visual>
    <collision>
      <geometry>
        <mesh filename="package://spot_urdf/meshes/rear_left_lower_leg_collision.stl"/>
      </geometry>
    </collision>
    <inertial>
      <origin rpy="0 0 0" xyz="0.002781 6.3e-05 -0.142518"/>
      <mass value="0.207"/>
      <inertia ixx="0.006341369" ixy="-3e-09" ixz="-8.7951e-05" iyy="0.006355157" iyz="-1.336e-06" izz="3.9188e-05"/>
    </inertial>
  </link>
  <joint name="lh_kfe_joint" type="revolute">
    <origin rpy="0 0 0" xyz="0.025 0.000 -0.3205"/>
    <axis xyz="0 1 0"/>
    <parent link="lh_upperleg"/>
    <child link="lh_lowerleg"/>
    <limit effort="1000" lower="-2.7929" upper="-0.267153" velocity="1000.00"/>
  </joint>
  <joint name="lh_foot_joint" type="fixed">
    <origin rpy="0 0 0" xyz="-0.005 0.0 -0.348"/>
    <parent link="lh_lowerleg"/>
    <child link="lh_foot"/>
  </joint>
  <link name="lh_foot">
    <visual>
      <origin rpy="0 0 0" xyz="0 0 0"/>
      <geometry>
        <sphere radius="0.019999999999999997"/>
      </geometry>
      <material name="green">
        <color rgba="0.0 0.8 0.0 1.0"/>
      </material>
    </visual>
    <collision>
      <origin rpy="0 0 0" xyz="0 0 0"/>
      <geometry>
        <sphere radius="0.03"/>
      </geometry>
    </collision>
    <inertial>
      <mass value="0.06"/>
      <inertia ixx="2.16e-05" ixy="0.0" ixz="0.0" iyy="2.16e-05" iyz="0.0" izz="2.16e-05"/>
    </inertial>
  </link>
  <link name="rh_hip">
    <visual>
      <geometry>
        <mesh filename="package://spot_urdf/meshes/rear_right_hip.dae"/>
      </geometry>
    </visual>
    <collision>
      <geometry>
        <mesh filename="package://spot_urdf/meshes/rear_right_hip_collision.stl"/>
      </geometry>
    </collision>
    <inertial>
      <origin rpy="0 0 0" xyz="0.022191 -0.015144 -1.5e-05"/>
      <mass value="1.993"/>
      <inertia ixx="0.002903894" ixy="-7.185e-05" ixz="1.262e-06" iyy="0.004907517" iyz="1.75e-06" izz="0.005586944"/>
    </inertial>
  </link>
  <joint name="rh_haa_joint" type="revolute">
    <origin rpy="0 0 0" xyz="-0.29785 -0.05500 0.00000"/>
    <axis xyz="1 0 0"/>
    <parent link="base_link"/>
    <child link="rh_hip"/>
    <limit effort="1000" lower="-0.78539816339744827899" upper="0.78539816339744827899" velocity="1000.00"/>
  </joint>
  <link name="rh_upperleg">
    <visual>
      <geometry>
        <mesh filename="package://spot_urdf/meshes/rear_right_upper_leg.dae"/>
      </geometry>
    </visual>
    <collision>
      <geometry>
        <mesh filename="package://spot_urdf/meshes/rear_right_upper_leg_collision.stl"/>
      </geometry>
    </collision>
    <inertial>
      <origin rpy="0 0 0" xyz="-0.005607 0.003877 -0.048199"/>
      <mass value="0.639"/>
      <inertia ixx="0.005666803" ixy="-3.597e-06" ixz="0.000491446" iyy="0.005847229" iyz="-1.0086e-05" izz="0.000369811"/>
    </inertial>
  </link>
  <joint name="rh_hfe_joint" type="revolute">
    <origin rpy="0 0 0" xyz="0.0 -0.110945 0.0"/>
    <axis xyz="0 1 0"/>
    <parent link="rh_hip"/>
    <child link="rh_upperleg"/>
    <limit effort="1000" lower="-0.89884456477707963539" upper="2.2951079663725435509" velocity="1000.00"/>
  </joint>
  <link name="rh_lowerleg">
    <visual>
      <geometry>
        <mesh filename="package://spot_urdf/meshes/rear_right_lower_leg.dae"/>
      </geometry>
    </visual>
    <collision>
      <geometry>
        <mesh filename="package://spot_urdf/meshes/rear_right_lower_leg_collision.stl"/>
      </geometry>
    </collision>
    <inertial>
      <origin rpy="0 0 0" xyz="0.002781 -6.3e-05 -0.142518"/>
      <mass value="0.207"/>
      <inertia ixx="0.006341369" ixy="3e-09" ixz="-8.7951e-05" iyy="0.006355157" iyz="1.336e-06" izz="3.9188e-05"/>
    </inertial>
  </link>
  <joint name="rh_kfe_joint" type="revolute">
    <origin rpy="0 0 0" xyz="0.025 0.000 -0.3205"/>
    <axis xyz="0 1 0"/>
    <parent link="rh_upperleg"/>
    <child link="rh_lowerleg"/>
    <limit effort="1000" lower="-2.7929" upper="-0.257725" velocity="1000.00"/>
  </joint>
  <joint name="rh_foot_joint" type="fixed">
    <origin rpy="0 0 0" xyz="-0.005 0.0 -0.348"/>
    <parent link="rh_lowerleg"/>
    <child link="rh_foot"/>
  </joint>
  <link name="rh_foot">
    <visual>
      <origin rpy="0 0 0" xyz="0 0 0"/>
      <geometry>
        <sphere radius="0.019999999999999997"/>
      </geometry>
      <material name="green">
        <color rgba="0.0 0.8 0.0 1.0"/>
      </material>
    </visual>
    <collision>
      <origin rpy="0 0 0" xyz="0 0 0"/>
      <geometry>
        <sphere radius="0.03"/>
      </geometry>
    </collision>
    <inertial>
      <mass value="0.06"/>
      <inertia ixx="2.16e-05" ixy="0.0" ixz="0.0" iyy="2.16e-05" iyz="0.0" izz="2.16e-05"/>
    </inertial>
  </link>
  <!-- Hip assembly -->
  <transmission name="rf_haa_trans">
    <type>transmission_interface/SimpleTransmission</type>
    <joint name="rf_haa_joint">
      <hardwareInterface>EffortJointInterface</hardwareInterface>
    </joint>
    <actuator name="rf_haa_motor">
      <hardwareInterface>EffortJointInterface</hardwareInterface>
      <mechanicalReduction>1</mechanicalReduction>
    </actuator>
  </transmission>
  <!-- Upper leg -->
  <transmission name="rf_hfe_trans">
    <type>transmission_interface/SimpleTransmission</type>
    <joint name="rf_hfe_joint">
      <hardwareInterface>EffortJointInterface</hardwareInterface>
    </joint>
    <actuator name="rf_hfe_motor">
      <hardwareInterface>EffortJointInterface</hardwareInterface>
      <mechanicalReduction>1</mechanicalReduction>
    </actuator>
  </transmission>
  <!-- Lower leg -->
  <transmission name="rf_kfe_trans">
    <type>transmission_interface/SimpleTransmission</type>
    <joint name="rf_kfe_joint">
      <hardwareInterface>EffortJointInterface</hardwareInterface>
    </joint>
    <actuator name="rf_kfe_motor">
      <hardwareInterface>EffortJointInterface</hardwareInterface>
      <mechanicalReduction>1</mechanicalReduction>
    </actuator>
  </transmission>
  <gazebo reference="rf_haa_joint">
    <provideFeedback>true</provideFeedback>
  </gazebo>
  <gazebo reference="rf_kfe_joint">
    <provideFeedback>true</provideFeedback>
  </gazebo>
  <gazebo reference="rf_hfe_joint">
    <provideFeedback>true</provideFeedback>
  </gazebo>
  <gazebo reference="rf_upperleg">
    <kp>1000000.0</kp>
    <kd>100.0</kd>
    <mu1>1.5</mu1>
    <mu2>1.5</mu2>
    <fdir1>1 0 0</fdir1>
    <maxVel>1.0</maxVel>
    <minDepth>0.00</minDepth>
  </gazebo>
  <gazebo reference="rf_lowerleg">
    <kp>1000000.0</kp>
    <kd>100.0</kd>
    <mu1>1.0</mu1>
    <mu2>1.0</mu2>
    <maxVel>1.0</maxVel>
    <maxContacts>1</maxContacts>
    <sensor name="rf_shin_contact_sensor" type="contact">
      <always_on>true</always_on>
      <update_rate>250.0</update_rate>
      <contact>
        <collision>rf_lowerleg_collision</collision>
      </contact>
      <!-- the sensor readings in terms of force torques are expressed in the lowerleg frame
                because gazebo lumps the fake footframe with the real parent link, the normals are in the world frame-->
      <plugin filename="libgazebo_ros_bumper.so" name="rf_shin_bumper">
        <bumperTopicName>/spot/rf_shin_bumper</bumperTopicName>
      </plugin>
    </sensor>
  </gazebo>
  <gazebo reference="rf_foot">
    <kp>1000000.0</kp>
    <kd>100.0</kd>
    <mu1>1.0</mu1>
    <mu2>1.0</mu2>
    <maxVel>1.0</maxVel>
    <maxContacts>1</maxContacts>
    <sensor name="rf_foot_contact_sensor" type="contact">
      <always_on>true</always_on>
      <update_rate>250.0</update_rate>
      <contact>
        <collision>rf_lowerleg_fixed_joint_lump__rf_foot_collision_1</collision>
      </contact>
      <!-- the sensor readings in terms of force torques are expressed in the lowerleg frame
                                because gazebo lumps the fake footframe with the real parent link, the normals are in the world frame-->
      <plugin filename="libgazebo_ros_bumper.so" name="rf_foot_bumper">
        <bumperTopicName>/spot/rf_foot_bumper</bumperTopicName>
        <robotNamespace>spot</robotNamespace>
      </plugin>
    </sensor>
    <material>Gazebo/Black</material>
  </gazebo>
  <!-- Hip assembly -->
  <transmission name="lf_haa_trans">
    <type>transmission_interface/SimpleTransmission</type>
    <joint name="lf_haa_joint">
      <hardwareInterface>EffortJointInterface</hardwareInterface>
    </joint>
    <actuator name="lf_haa_motor">
      <hardwareInterface>EffortJointInterface</hardwareInterface>
      <mechanicalReduction>1</mechanicalReduction>
    </actuator>
  </transmission>
  <!-- Upper leg -->
  <transmission name="lf_hfe_trans">
    <type>transmission_interface/SimpleTransmission</type>
    <joint name="lf_hfe_joint">
      <hardwareInterface>EffortJointInterface</hardwareInterface>
    </joint>
    <actuator name="lf_hfe_motor">
      <hardwareInterface>EffortJointInterface</hardwareInterface>
      <mechanicalReduction>1</mechanicalReduction>
    </actuator>
  </transmission>
  <!-- Lower leg -->
  <transmission name="lf_kfe_trans">
    <type>transmission_interface/SimpleTransmission</type>
    <joint name="lf_kfe_joint">
      <hardwareInterface>EffortJointInterface</hardwareInterface>
    </joint>
    <actuator name="lf_kfe_motor">
      <hardwareInterface>EffortJointInterface</hardwareInterface>
      <mechanicalReduction>1</mechanicalReduction>
    </actuator>
  </transmission>
  <gazebo reference="lf_haa_joint">
    <provideFeedback>true</provideFeedback>
  </gazebo>
  <gazebo reference="lf_kfe_joint">
    <provideFeedback>true</provideFeedback>
  </gazebo>
  <gazebo reference="lf_hfe_joint">
    <provideFeedback>true</provideFeedback>
  </gazebo>
  <gazebo reference="lf_upperleg">
    <kp>1000000.0</kp>
    <kd>100.0</kd>
    <mu1>1.5</mu1>
    <mu2>1.5</mu2>
    <fdir1>1 0 0</fdir1>
    <maxVel>1.0</maxVel>
    <minDepth>0.00</minDepth>
  </gazebo>
  <gazebo reference="lf_lowerleg">
    <kp>1000000.0</kp>
    <kd>100.0</kd>
    <mu1>1.0</mu1>
    <mu2>1.0</mu2>
    <maxVel>1.0</maxVel>
    <maxContacts>1</maxContacts>
    <sensor name="lf_shin_contact_sensor" type="contact">
      <always_on>true</always_on>
      <update_rate>250.0</update_rate>
      <contact>
        <collision>lf_lowerleg_collision</collision>
      </contact>
      <!-- the sensor readings in terms of force torques are expressed in the lowerleg frame
                because gazebo lumps the fake footframe with the real parent link, the normals are in the world frame-->
      <plugin filename="libgazebo_ros_bumper.so" name="lf_shin_bumper">
        <bumperTopicName>/spot/lf_shin_bumper</bumperTopicName>
      </plugin>
    </sensor>
  </gazebo>
  <gazebo reference="lf_foot">
    <kp>1000000.0</kp>
    <kd>100.0</kd>
    <mu1>1.0</mu1>
    <mu2>1.0</mu2>
    <maxVel>1.0</maxVel>
    <maxContacts>1</maxContacts>
    <sensor name="lf_foot_contact_sensor" type="contact">
      <always_on>true</always_on>
      <update_rate>250.0</update_rate>
      <contact>
        <collision>lf_lowerleg_fixed_joint_lump__lf_foot_collision_1</collision>
      </contact>
      <!-- the sensor readings in terms of force torques are expressed in the lowerleg frame
                                because gazebo lumps the fake footframe with the real parent link, the normals are in the world frame-->
      <plugin filename="libgazebo_ros_bumper.so" name="lf_foot_bumper">
        <bumperTopicName>/spot/lf_foot_bumper</bumperTopicName>
        <robotNamespace>spot</robotNamespace>
      </plugin>
    </sensor>
    <material>Gazebo/Black</material>
  </gazebo>
  <!-- Hip assembly -->
  <transmission name="rh_haa_trans">
    <type>transmission_interface/SimpleTransmission</type>
    <joint name="rh_haa_joint">
      <hardwareInterface>EffortJointInterface</hardwareInterface>
    </joint>
    <actuator name="rh_haa_motor">
      <hardwareInterface>EffortJointInterface</hardwareInterface>
      <mechanicalReduction>1</mechanicalReduction>
    </actuator>
  </transmission>
  <!-- Upper leg -->
  <transmission name="rh_hfe_trans">
    <type>transmission_interface/SimpleTransmission</type>
    <joint name="rh_hfe_joint">
      <hardwareInterface>EffortJointInterface</hardwareInterface>
    </joint>
    <actuator name="rh_hfe_motor">
      <hardwareInterface>EffortJointInterface</hardwareInterface>
      <mechanicalReduction>1</mechanicalReduction>
    </actuator>
  </transmission>
  <!-- Lower leg -->
  <transmission name="rh_kfe_trans">
    <type>transmission_interface/SimpleTransmission</type>
    <joint name="rh_kfe_joint">
      <hardwareInterface>EffortJointInterface</hardwareInterface>
    </joint>
    <actuator name="rh_kfe_motor">
      <hardwareInterface>EffortJointInterface</hardwareInterface>
      <mechanicalReduction>1</mechanicalReduction>
    </actuator>
  </transmission>
  <gazebo reference="rh_haa_joint">
    <provideFeedback>true</provideFeedback>
  </gazebo>
  <gazebo reference="rh_kfe_joint">
    <provideFeedback>true</provideFeedback>
  </gazebo>
  <gazebo reference="rh_hfe_joint">
    <provideFeedback>true</provideFeedback>
  </gazebo>
  <gazebo reference="rh_upperleg">
    <kp>1000000.0</kp>
    <kd>100.0</kd>
    <mu1>1.5</mu1>
    <mu2>1.5</mu2>
    <fdir1>1 0 0</fdir1>
    <maxVel>1.0</maxVel>
    <minDepth>0.00</minDepth>
  </gazebo>
  <gazebo reference="rh_lowerleg">
    <kp>1000000.0</kp>
    <kd>100.0</kd>
    <mu1>1.0</mu1>
    <mu2>1.0</mu2>
    <maxVel>1.0</maxVel>
    <maxContacts>1</maxContacts>
    <sensor name="rh_shin_contact_sensor" type="contact">
      <always_on>true</always_on>
      <update_rate>250.0</update_rate>
      <contact>
        <collision>rh_lowerleg_collision</collision>
      </contact>
      <!-- the sensor readings in terms of force torques are expressed in the lowerleg frame
                because gazebo lumps the fake footframe with the real parent link, the normals are in the world frame-->
      <plugin filename="libgazebo_ros_bumper.so" name="rh_shin_bumper">
        <bumperTopicName>/spot/rh_shin_bumper</bumperTopicName>
      </plugin>
    </sensor>
  </gazebo>
  <gazebo reference="rh_foot">
    <kp>1000000.0</kp>
    <kd>100.0</kd>
    <mu1>1.0</mu1>
    <mu2>1.0</mu2>
    <maxVel>1.0</maxVel>
    <maxContacts>1</maxContacts>
    <sensor name="rh_foot_contact_sensor" type="contact">
      <always_on>true</always_on>
      <update_rate>250.0</update_rate>
      <contact>
        <collision>rh_lowerleg_fixed_joint_lump__rh_foot_collision_1</collision>
      </contact>
      <!-- the sensor readings in terms of force torques are expressed in the lowerleg frame
                                because gazebo lumps the fake footframe with the real parent link, the normals are in the world frame-->
      <plugin filename="libgazebo_ros_bumper.so" name="rh_foot_bumper">
        <bumperTopicName>/spot/rh_foot_bumper</bumperTopicName>
        <robotNamespace>spot</robotNamespace>
      </plugin>
    </sensor>
    <material>Gazebo/Black</material>
  </gazebo>
  <!-- Hip assembly -->
  <transmission name="lh_haa_trans">
    <type>transmission_interface/SimpleTransmission</type>
    <joint name="lh_haa_joint">
      <hardwareInterface>EffortJointInterface</hardwareInterface>
    </joint>
    <actuator name="lh_haa_motor">
      <hardwareInterface>EffortJointInterface</hardwareInterface>
      <mechanicalReduction>1</mechanicalReduction>
    </actuator>
  </transmission>
  <!-- Upper leg -->
  <transmission name="lh_hfe_trans">
    <type>transmission_interface/SimpleTransmission</type>
    <joint name="lh_hfe_joint">
      <hardwareInterface>EffortJointInterface</hardwareInterface>
    </joint>
    <actuator name="lh_hfe_motor">
      <hardwareInterface>EffortJointInterface</hardwareInterface>
      <mechanicalReduction>1</mechanicalReduction>
    </actuator>
  </transmission>
  <!-- Lower leg -->
  <transmission name="lh_kfe_trans">
    <type>transmission_interface/SimpleTransmission</type>
    <joint name="lh_kfe_joint">
      <hardwareInterface>EffortJointInterface</hardwareInterface>
    </joint>
    <actuator name="lh_kfe_motor">
      <hardwareInterface>EffortJointInterface</hardwareInterface>
      <mechanicalReduction>1</mechanicalReduction>
    </actuator>
  </transmission>
  <gazebo reference="lh_haa_joint">
    <provideFeedback>true</provideFeedback>
  </gazebo>
  <gazebo reference="lh_kfe_joint">
    <provideFeedback>true</provideFeedback>
  </gazebo>
  <gazebo reference="lh_hfe_joint">
    <provideFeedback>true</provideFeedback>
  </gazebo>
  <gazebo reference="lh_upperleg">
    <kp>1000000.0</kp>
    <kd>100.0</kd>
    <mu1>1.5</mu1>
    <mu2>1.5</mu2>
    <fdir1>1 0 0</fdir1>
    <maxVel>1.0</maxVel>
    <minDepth>0.00</minDepth>
  </gazebo>
  <gazebo reference="lh_lowerleg">
    <kp>1000000.0</kp>
    <kd>100.0</kd>
    <mu1>1.0</mu1>
    <mu2>1.0</mu2>
    <maxVel>1.0</maxVel>
    <maxContacts>1</maxContacts>
    <sensor name="lh_shin_contact_sensor" type="contact">
      <always_on>true</always_on>
      <update_rate>250.0</update_rate>
      <contact>
        <collision>lh_lowerleg_collision</collision>
      </contact>
      <!-- the sensor readings in terms of force torques are expressed in the lowerleg frame
                because gazebo lumps the fake footframe with the real parent link, the normals are in the world frame-->
      <plugin filename="libgazebo_ros_bumper.so" name="lh_shin_bumper">
        <bumperTopicName>/spot/lh_shin_bumper</bumperTopicName>
      </plugin>
    </sensor>
  </gazebo>
  <gazebo reference="lh_foot">
    <kp>1000000.0</kp>
    <kd>100.0</kd>
    <mu1>1.0</mu1>
    <mu2>1.0</mu2>
    <maxVel>1.0</maxVel>
    <maxContacts>1</maxContacts>
    <sensor name="lh_foot_contact_sensor" type="contact">
      <always_on>true</always_on>
      <update_rate>250.0</update_rate>
      <contact>
        <collision>lh_lowerleg_fixed_joint_lump__lh_foot_collision_1</collision>
      </contact>
      <!-- the sensor readings in terms of force torques are expressed in the lowerleg frame
                                because gazebo lumps the fake footframe with the real parent link, the normals are in the world frame-->
      <plugin filename="libgazebo_ros_bumper.so" name="lh_foot_bumper">
        <bumperTopicName>/spot/lh_foot_bumper</bumperTopicName>
        <robotNamespace>spot</robotNamespace>
      </plugin>
    </sensor>
    <material>Gazebo/Black</material>
  </gazebo>
</robot>
